<?xml version="1.0" ?>
<!-- =================================================================================== -->
<!-- |    This document was autogenerated by xacro from /home/coro/ros2_ws/src/doosan-robot2/dsr_description2/xacro/m1013.urdf.xacro | -->
<!-- |    EDITING THIS FILE BY HAND IS NOT RECOMMENDED                                 | -->
<!-- =================================================================================== -->
<robot name="m1013">
  <material name="black">
    <color rgba="0.0 0.0 0.0 1.0"/>
  </material>
  <material name="white">
    <color rgba="1.0 1.0 1.0 1.0"/>
  </material>
  <material name="orange">
    <color rgba="1.0 0.4 0.0 1.0"/>
  </material>
  <material name="dr_gray">
    <color rgba="0.490 0.490 0.486 1.0"/>
  </material>
  <material name="dr_white">
    <color rgba="0.941 0.941 0.941 1.0"/>
  </material>
  <link name="base_0">
    <inertial>
      <mass value="4.12"/>
      <origin xyz="-3.4e-05   -0.004815    0.048482"/>
      <inertia ixx="0.016331" ixy="-6.4837e-06" ixz="2.0048e-06" iyy="0.014945" iyz="-0.00051686" izz="0.022577"/>
    </inertial>
    <collision>
      <origin rpy="0 0 0" xyz="0 0 0"/>
      <geometry>
        <mesh filename="/home/coro/ros2_ws/src/m1013/meshes/m1013_collision/MF1013_0_0.dae" scale="0.001 0.001 0.001"/>
      </geometry>
    </collision>
    <visual>
      <origin rpy="0 0 0" xyz="0 0 0"/>
      <geometry>
        <mesh filename="/home/coro/ros2_ws/src/m1013/meshes/m1013_white/MF1013_0_0.dae" scale="0.001 0.001 0.001"/>
      </geometry>
    </visual>
  </link>
  <!-- joint 1 -->
  <joint name="joint1" type="revolute">
    <parent link="base_0"/>
    <child link="link1"/>
    <origin rpy="0 0 0" xyz="0 0 0.1525"/>
    <axis xyz="0 0 1"/>
    <limit effort="346" lower="-6.2832" upper="6.2832" velocity="2.0944"/>
    <dynamics friction="0"/>
  </joint>
  <link name="link1">
    <inertial>
      <mass value="7.8"/>
      <origin xyz="0.000119      0.0428   -0.006383"/>
      <inertia ixx="0.04506" ixy="4.1126e-05" ixz="-5.2533e-05" iyy="0.029679" iyz="-0.0019959" izz="0.047056"/>
    </inertial>
    <collision>
      <origin rpy="0 0 0" xyz="0 0 0"/>
      <geometry>
        <mesh filename="/home/coro/ros2_ws/src/m1013/meshes/m1013_collision/MF1013_1_0.dae" scale="0.001 0.001 0.001"/>
      </geometry>
    </collision>
    <visual>
      <origin rpy="0 0 0" xyz="0 0 0"/>
      <geometry>
        <mesh filename="/home/coro/ros2_ws/src/m1013/meshes/m1013_white/MF1013_1_0.dae" scale="0.001 0.001 0.001"/>
      </geometry>
    </visual>
  </link>
  <!-- joint2 -->
  <joint name="joint2" type="revolute">
    <parent link="link1"/>
    <child link="link2"/>
    <origin rpy="0 -1.571 -1.571" xyz="0 0.0345 0"/>
    <axis xyz="0 0 1"/>
    <limit effort="346" lower="-6.2832" upper="6.2832" velocity="2.0944"/>
    <dynamics friction="0"/>
  </joint>
  <link name="link2">
    <inertial>
      <mass value="10.83"/>
      <origin xyz="0.25973    -5.3e-05     0.15782"/>
      <inertia ixx="0.037586" ixy="-0.00036999" ixz="-0.0069927" iyy="0.84943" iyz="4.0201e-05" izz="0.85021"/>
    </inertial>
    <collision>
      <origin rpy="0 0 0" xyz="0 0 0"/>
      <geometry>
        <mesh filename="/home/coro/ros2_ws/src/m1013/meshes/m1013_collision/MF1013_2_0.dae" scale="0.001 0.001 0.001"/>
      </geometry>
    </collision>
    <visual>
      <origin rpy="0 0 0" xyz="0 0 0"/>
      <geometry>
        <mesh filename="/home/coro/ros2_ws/src/m1013/meshes/m1013_white/MF1013_2_0.dae" scale="0.001 0.001 0.001"/>
      </geometry>
    </visual>
    <collision>
      <origin rpy="0 0 0" xyz="0 0 0"/>
      <geometry>
        <mesh filename="/home/coro/ros2_ws/src/m1013/meshes/m1013_collision/MF1013_2_1.dae" scale="0.001 0.001 0.001"/>
      </geometry>
    </collision>
    <visual>
      <origin rpy="0 0 0" xyz="0 0 0"/>
      <geometry>
        <mesh filename="/home/coro/ros2_ws/src/m1013/meshes/m1013_white/MF1013_2_1.dae" scale="0.001 0.001 0.001"/>
      </geometry>
    </visual>
    <collision>
      <origin rpy="0 0 0" xyz="0 0 0"/>
      <geometry>
        <mesh filename="/home/coro/ros2_ws/src/m1013/meshes/m1013_collision/MF1013_2_2.dae" scale="0.001 0.001 0.001"/>
      </geometry>
    </collision>
    <visual>
      <origin rpy="0 0 0" xyz="0 0 0"/>
      <geometry>
        <mesh filename="/home/coro/ros2_ws/src/m1013/meshes/m1013_white/MF1013_2_2.dae" scale="0.001 0.001 0.001"/>
      </geometry>
    </visual>
  </link>
  <!-- joint3 -->
  <joint name="joint3" type="revolute">
    <parent link="link2"/>
    <child link="link3"/>
    <origin rpy="0 0 1.571" xyz="0.62 0 0"/>
    <axis xyz="0 0 1"/>
    <limit effort="163" lower="-2.7925" upper="2.7925" velocity="3.1416"/>
    <dynamics friction="0"/>
  </joint>
  <link name="link3">
    <inertial>
      <mass value="3.68"/>
      <origin xyz="-1.5e-05   -0.006702    0.044608"/>
      <inertia ixx="0.018748" ixy="7.8071e-06" ixz="-5.0324e-06" iyy="0.018972" iyz="-0.00099342" izz="0.011502"/>
    </inertial>
    <collision>
      <origin rpy="0 0 0" xyz="0 0 0"/>
      <geometry>
        <mesh filename="/home/coro/ros2_ws/src/m1013/meshes/m1013_collision/MF1013_3_0.dae" scale="0.001 0.001 0.001"/>
      </geometry>
    </collision>
    <visual>
      <origin rpy="0 0 0" xyz="0 0 0"/>
      <geometry>
        <mesh filename="/home/coro/ros2_ws/src/m1013/meshes/m1013_white/MF1013_3_0.dae" scale="0.001 0.001 0.001"/>
      </geometry>
    </visual>
  </link>
  <!-- joint4 -->
  <joint name="joint4" type="revolute">
    <parent link="link3"/>
    <child link="link4"/>
    <origin rpy="1.571 0 0" xyz="0 -0.559 0"/>
    <axis xyz="0 0 1"/>
    <limit effort="50" lower="-6.2832" upper="6.2832" velocity="3.927"/>
    <dynamics friction="0"/>
  </joint>
  <link name="link4">
    <inertial>
      <mass value="3.82"/>
      <origin xyz="7.1e-05    0.091879    -0.18252"/>
      <inertia ixx="0.19063" ixy="-1.8037e-05" ixz="-3.8576e-05" iyy="0.17268" iyz="-0.052996" izz="0.030386"/>
    </inertial>
    <collision>
      <origin rpy="0 0 0" xyz="0 0 0"/>
      <geometry>
        <mesh filename="/home/coro/ros2_ws/src/m1013/meshes/m1013_collision/MF1013_4_0.dae" scale="0.001 0.001 0.001"/>
      </geometry>
    </collision>
    <visual>
      <origin rpy="0 0 0" xyz="0 0 0"/>
      <geometry>
        <mesh filename="/home/coro/ros2_ws/src/m1013/meshes/m1013_white/MF1013_4_0.dae" scale="0.001 0.001 0.001"/>
      </geometry>
    </visual>
    <collision>
      <origin rpy="0 0 0" xyz="0 0 0"/>
      <geometry>
        <mesh filename="/home/coro/ros2_ws/src/m1013/meshes/m1013_collision/MF1013_4_1.dae" scale="0.001 0.001 0.001"/>
      </geometry>
    </collision>
    <visual>
      <origin rpy="0 0 0" xyz="0 0 0"/>
      <geometry>
        <mesh filename="/home/coro/ros2_ws/src/m1013/meshes/m1013_white/MF1013_4_1.dae" scale="0.001 0.001 0.001"/>
      </geometry>
    </visual>
  </link>
  <!-- joint5 -->
  <joint name="joint5" type="revolute">
    <parent link="link4"/>
    <child link="link5"/>
    <origin rpy="-1.571 0 0" xyz="0 0 0"/>
    <axis xyz="0 0 1"/>
    <limit effort="50" lower="-6.2832" upper="6.2832" velocity="3.927"/>
    <dynamics friction="0"/>
  </joint>
  <link name="link5">
    <inertial>
      <mass value="2.82"/>
      <origin xyz="-0.000273    0.003651    0.032088"/>
      <inertia ixx="0.015583" ixy="2.135e-05" ixz="-5.1895e-06" iyy="0.011519" iyz="0.00042553" izz="0.0088671"/>
    </inertial>
    <collision>
      <origin rpy="0 0 0" xyz="0 0 0"/>
      <geometry>
        <mesh filename="/home/coro/ros2_ws/src/m1013/meshes/m1013_collision/MF1013_5_0.dae" scale="0.001 0.001 0.001"/>
      </geometry>
    </collision>
    <visual>
      <origin rpy="0 0 0" xyz="0 0 0"/>
      <geometry>
        <mesh filename="/home/coro/ros2_ws/src/m1013/meshes/m1013_white/MF1013_5_0.dae" scale="0.001 0.001 0.001"/>
      </geometry>
    </visual>
  </link>
  <!-- joint6 -->
  <joint name="joint6" type="revolute">
    <parent link="link5"/>
    <child link="link6"/>
    <origin rpy="1.571 0 0" xyz="0 -0.121 0"/>
    <axis xyz="0 0 1"/>
    <limit effort="50" lower="-6.2832" upper="6.2832" velocity="3.927"/>
    <dynamics friction="0"/>
  </joint>
  <link name="link6">
    <inertial>
      <mass value="1.16"/>
      <origin xyz="-0.000292       7e-06     -0.0539"/>
      <inertia ixx="0.0048282" ixy="4.1298e-06" ixz="6.9879e-06" iyy="0.0059519" iyz="4.252e-06" izz="0.0061263"/>
    </inertial>
    <collision>
      <origin rpy="0 0 0" xyz="0 0 0"/>
      <geometry>
        <mesh filename="/home/coro/ros2_ws/src/m1013/meshes/m1013_collision/MF1013_6_0.dae" scale="0.001 0.001 0.001"/>
      </geometry>
    </collision>
    <visual>
      <origin rpy="0 0 0" xyz="0 0 0"/>
      <geometry>
        <mesh filename="/home/coro/ros2_ws/src/m1013/meshes/m1013_white/MF1013_6_0.dae" scale="0.001 0.001 0.001"/>
      </geometry>
    </visual>
  </link>
  <!-- Transmission 1 -->
  <transmission name="tran1">
    <type>transmission_interface/SimpleTransmission</type>
    <joint name="joint1">
      <hardwareInterface>hardware_interface/PositionJointInterface</hardwareInterface>
    </joint>
    <actuator name="motor1">
      <hardwareInterface>hardware_interface/PositionJointInterface</hardwareInterface>
      <mechanicalReduction>1</mechanicalReduction>
    </actuator>
  </transmission>
  <!-- Transmission 2 -->
  <transmission name="tran2">
    <type>transmission_interface/SimpleTransmission</type>
    <joint name="joint2">
      <hardwareInterface>hardware_interface/PositionJointInterface</hardwareInterface>
    </joint>
    <actuator name="motor2">
      <hardwareInterface>hardware_interface/PositionJointInterface</hardwareInterface>
      <mechanicalReduction>1</mechanicalReduction>
    </actuator>
  </transmission>
  <!-- Transmission 3 -->
  <transmission name="tran3">
    <type>transmission_interface/SimpleTransmission</type>
    <joint name="joint3">
      <hardwareInterface>hardware_interface/PositionJointInterface</hardwareInterface>
    </joint>
    <actuator name="motor3">
      <hardwareInterface>hardware_interface/PositionJointInterface</hardwareInterface>
      <mechanicalReduction>1</mechanicalReduction>
    </actuator>
  </transmission>
  <!-- Transmission 4 -->
  <transmission name="tran4">
    <type>transmission_interface/SimpleTransmission</type>
    <joint name="joint4">
      <hardwareInterface>hardware_interface/PositionJointInterface</hardwareInterface>
    </joint>
    <actuator name="motor4">
      <hardwareInterface>hardware_interface/PositionJointInterface</hardwareInterface>
      <mechanicalReduction>1</mechanicalReduction>
    </actuator>
  </transmission>
  <!-- Transmission 5 -->
  <transmission name="tran5">
    <type>transmission_interface/SimpleTransmission</type>
    <joint name="joint5">
      <hardwareInterface>hardware_interface/PositionJointInterface</hardwareInterface>
    </joint>
    <actuator name="motor5">
      <hardwareInterface>hardware_interface/PositionJointInterface</hardwareInterface>
      <mechanicalReduction>1</mechanicalReduction>
    </actuator>
  </transmission>
  <!-- Transmission 6 -->
  <transmission name="tran6">
    <type>transmission_interface/SimpleTransmission</type>
    <joint name="joint6">
      <hardwareInterface>hardware_interface/PositionJointInterface</hardwareInterface>
    </joint>
    <actuator name="motor6">
      <hardwareInterface>hardware_interface/PositionJointInterface</hardwareInterface>
      <mechanicalReduction>1</mechanicalReduction>
    </actuator>
  </transmission>
  <!-- Base -->
  <gazebo reference="base_0">
    <kp>1000000.0</kp>
    <kd>100.0</kd>
    <mu1>30.0</mu1>
    <mu2>30.0</mu2>
    <maxVel>1.0</maxVel>
    <minDepth>0.001</minDepth>
  </gazebo>
  <!-- Link1 -->
  <gazebo reference="link1">
    <kp>1000000.0</kp>
    <kd>100.0</kd>
    <mu1>30.0</mu1>
    <mu2>30.0</mu2>
    <maxVel>1.0</maxVel>
    <minDepth>0.001</minDepth>
  </gazebo>
  <!-- Link2 -->
  <gazebo reference="link2">
    <kp>1000000.0</kp>
    <kd>100.0</kd>
    <mu1>30.0</mu1>
    <mu2>30.0</mu2>
    <maxVel>1.0</maxVel>
    <minDepth>0.001</minDepth>
  </gazebo>
  <!-- Link3 -->
  <gazebo reference="link3">
    <kp>1000000.0</kp>
    <kd>100.0</kd>
    <mu1>30.0</mu1>
    <mu2>30.0</mu2>
    <maxVel>1.0</maxVel>
    <minDepth>0.001</minDepth>
  </gazebo>
  <!-- Link4 -->
  <gazebo reference="link4">
    <kp>1000000.0</kp>
    <kd>100.0</kd>
    <mu1>30.0</mu1>
    <mu2>30.0</mu2>
    <maxVel>1.0</maxVel>
    <minDepth>0.001</minDepth>
  </gazebo>
  <!-- Link5 -->
  <gazebo reference="link5">
    <kp>1000000.0</kp>
    <kd>100.0</kd>
    <mu1>30.0</mu1>
    <mu2>30.0</mu2>
    <maxVel>1.0</maxVel>
    <minDepth>0.001</minDepth>
  </gazebo>
  <!-- Link6 -->
  <gazebo reference="link6">
    <kp>1000000.0</kp>
    <kd>100.0</kd>
    <mu1>30.0</mu1>
    <mu2>30.0</mu2>
    <maxVel>1.0</maxVel>
    <minDepth>0.001</minDepth>
  </gazebo>
  <!-- ros_control plugin -->
  <gazebo>
    <plugin filename="libgazebo_ros2_control.so" name="gazebo_ros2_control">
      <!--ros>
          <namespace>/</namespace>
            <parameter name="joint1.p" type="double">400.0</parameter>
            <parameter name="joint1.i" type="double">0.0</parameter>
          <parameter name="joint1.d" type="double">40.0</parameter>

            <parameter name="joint2.p" type="double">400.0</parameter>
            <parameter name="joint2.i" type="double">0.0</parameter>
          <parameter name="joint2.d" type="double">40.0</parameter>

            <parameter name="joint3.p" type="double">1000.0</parameter>
            <parameter name="joint3.i" type="double">0.0</parameter>
          <parameter name="joint3.d" type="double">10.0</parameter>

            <parameter name="joint4.p" type="double">800.0</parameter>
            <parameter name="joint4.i" type="double">0.0</parameter>
          <parameter name="joint4.d" type="double">30.0</parameter>

            <parameter name="joint5.p" type="double">1500.0</parameter>
            <parameter name="joint5.i" type="double">0.0</parameter>
          <parameter name="joint5.d" type="double">10.0</parameter>

            <parameter name="joint6.p" type="double">1500.0</parameter>
            <parameter name="joint6.i" type="double">0.0</parameter>
          <parameter name="joint6.d" type="double">10.0</parameter>
        </ros-->
      <robot_sim_type>gazebo_ros2_control/DefaultRobotHWSim</robot_sim_type>
      <parameters>/home/coro/ros2_ws/src/doosan-robot2/dsr_controller2/config/dsr_controller2.yaml</parameters>
    </plugin>
  </gazebo>
  <link name="world"/>
  <!-- World fixed joint-->
  <joint name="world_fixed" type="fixed">
    <origin rpy="0 0 0" xyz="0 0 0"/>
    <parent link="world"/>
    <child link="base_0"/>
  </joint>
  <ros2_control name="m1013" type="system">
    <hardware>
      <plugin>dsr_hardware2/DRHWInterface</plugin>
      <param name="name">m1013</param>
      <param name="rate">100</param>
      <param name="standby">ture</param>
      <param name="command">none</param>
      <param name="host">0.0.0.0</param>
      <param name="port">12345</param>
      <param name="mode">real</param>
      <param name="model">m1013</param>
      <param name="gripper">none</param>
      <param name="mobile">none</param>
    </hardware>
    <joint name="joint1">
      <command_interface name="position">
        <param name="min">{-2*pi}</param>
        <param name="max">{2*pi}</param>
      </command_interface>
      <command_interface name="velocity">
        <param name="min">-3.15</param>
        <param name="max">3.15</param>
      </command_interface>
      <state_interface name="position">
        <param name="initial_value">0.0</param>
      </state_interface>
      <state_interface name="velocity"/>
    </joint>
    <joint name="joint2">
      <command_interface name="position">
        <param name="min">{-2*pi}</param>
        <param name="max">{2*pi}</param>
      </command_interface>
      <command_interface name="velocity">
        <param name="min">-3.15</param>
        <param name="max">3.15</param>
      </command_interface>
      <state_interface name="position">
        <param name="initial_value">0.0</param>
      </state_interface>
      <state_interface name="velocity"/>
    </joint>
    <joint name="joint3">
      <command_interface name="position">
        <param name="min">{-pi}</param>
        <param name="max">{pi}</param>
      </command_interface>
      <command_interface name="velocity">
        <param name="min">-3.15</param>
        <param name="max">3.15</param>
      </command_interface>
      <state_interface name="position">
        <param name="initial_value">0.0</param>
      </state_interface>
      <state_interface name="velocity"/>
    </joint>
    <joint name="joint4">
      <command_interface name="position">
        <param name="min">{-2*pi}</param>
        <param name="max">{2*pi}</param>
      </command_interface>
      <command_interface name="velocity">
        <param name="min">-3.2</param>
        <param name="max">3.2</param>
      </command_interface>
      <state_interface name="position">
        <param name="initial_value">0.0</param>
      </state_interface>
      <state_interface name="velocity"/>
    </joint>
    <joint name="joint5">
      <command_interface name="position">
        <param name="min">{-2*pi}</param>
        <param name="max">{2*pi}</param>
      </command_interface>
      <command_interface name="velocity">
        <param name="min">-3.2</param>
        <param name="max">3.2</param>
      </command_interface>
      <state_interface name="position">
        <param name="initial_value">0.0</param>
      </state_interface>
      <state_interface name="velocity"/>
    </joint>
    <joint name="joint6">
      <command_interface name="position">
        <param name="min">{-2*pi}</param>
        <param name="max">{2*pi}</param>
      </command_interface>
      <command_interface name="velocity">
        <param name="min">-3.2</param>
        <param name="max">3.2</param>
      </command_interface>
      <state_interface name="position">
        <param name="initial_value">0.0</param>
      </state_interface>
      <state_interface name="velocity"/>
    </joint>
  </ros2_control>
</robot>
